/home/tu/tu_tu/tu_zxolr37/.conda/envs/surprisal-cpu/lib/python3.11/site-packages/torch/cuda/__init__.py:829: UserWarning: Can't initialize NVML
  warnings.warn("Can't initialize NVML")
/home/tu/tu_tu/tu_zxolr37/.conda/envs/surprisal-cpu/lib/python3.11/site-packages/wandb/sdk/launch/builder/build.py:11: UserWarning: pkg_resources is deprecated as an API. See https://setuptools.pypa.io/en/latest/pkg_resources.html. The pkg_resources package is slated for removal as early as 2025-11-30. Refrain from using this package or pin to Setuptools<81.
  import pkg_resources
Could not set the permissions on the file '_cashe/models--gpt2/blobs/248dfc3911869ec493c76e65bf2fcf7f615828b0254c12b473182f0f81d3a707.incomplete'. Error: [Errno 2] No such file or directory: '_cashe/models--gpt2/blobs/248dfc3911869ec493c76e65bf2fcf7f615828b0254c12b473182f0f81d3a707.incomplete'.
Continuing without setting permissions.
Traceback (most recent call last):
  File "/gpfs/bwfor/home/tu/tu_tu/tu_zxolr37/surprisal_internal_layers/src/EZ_run_gpt2_transformer_lens.py", line 125, in <module>
    main()
  File "/home/tu/tu_tu/tu_zxolr37/.conda/envs/surprisal-cpu/lib/python3.11/site-packages/torch/utils/_contextlib.py", line 120, in decorate_context
    return func(*args, **kwargs)
           ^^^^^^^^^^^^^^^^^^^^^
  File "/gpfs/bwfor/home/tu/tu_tu/tu_zxolr37/surprisal_internal_layers/src/EZ_run_gpt2_transformer_lens.py", line 45, in main
    gpt2_model = HookedTransformer.from_pretrained(args.model, device=device,cache_dir=args.cache,     fold_ln=False,
                 ^^^^^^^^^^^^^^^^^^^^^^^^^^^^^^^^^^^^^^^^^^^^^^^^^^^^^^^^^^^^^^^^^^^^^^^^^^^^^^^^^^^^^^^^^^^^^^^^^^^^
  File "/home/tu/tu_tu/tu_zxolr37/.conda/envs/surprisal-cpu/lib/python3.11/site-packages/transformer_lens/HookedTransformer.py", line 1375, in from_pretrained
    model = cls(
            ^^^^
  File "/home/tu/tu_tu/tu_zxolr37/.conda/envs/surprisal-cpu/lib/python3.11/site-packages/transformer_lens/HookedTransformer.py", line 165, in __init__
    AutoTokenizer.from_pretrained(
  File "/home/tu/tu_tu/tu_zxolr37/.conda/envs/surprisal-cpu/lib/python3.11/site-packages/transformers/models/auto/tokenization_auto.py", line 1049, in from_pretrained
    tokenizer_config = get_tokenizer_config(pretrained_model_name_or_path, **kwargs)
                       ^^^^^^^^^^^^^^^^^^^^^^^^^^^^^^^^^^^^^^^^^^^^^^^^^^^^^^^^^^^^^
  File "/home/tu/tu_tu/tu_zxolr37/.conda/envs/surprisal-cpu/lib/python3.11/site-packages/transformers/models/auto/tokenization_auto.py", line 903, in get_tokenizer_config
    result = json.load(reader)
             ^^^^^^^^^^^^^^^^^
  File "/home/tu/tu_tu/tu_zxolr37/.conda/envs/surprisal-cpu/lib/python3.11/json/__init__.py", line 293, in load
    return loads(fp.read(),
           ^^^^^^^^^^^^^^^^
  File "/home/tu/tu_tu/tu_zxolr37/.conda/envs/surprisal-cpu/lib/python3.11/json/__init__.py", line 346, in loads
    return _default_decoder.decode(s)
           ^^^^^^^^^^^^^^^^^^^^^^^^^^
  File "/home/tu/tu_tu/tu_zxolr37/.conda/envs/surprisal-cpu/lib/python3.11/json/decoder.py", line 340, in decode
    raise JSONDecodeError("Extra data", s, end)
json.decoder.JSONDecodeError: Extra data: line 1 column 27 (char 26)
